Workbook

Sheet Indicators - Classified
A1: # | B1: Mexicali indicator | C1: Domain | D1: Domain | L1: Subdomain | M1: Indicator / Category | N1: Subject | O1: Lens / Enfoque | V1: Reason this matters (draft) | Y1: Can we calculate this? Do we have data for Mexicali? (0: No / 1: Yes / 2: TBD) | Z1: What is the most pragmatic way of measuring it? | AA1: Article # | AB1: Excluded indicator | AC1: Methods sub-indices/measures | AD1: Potential data sources | AE1: Notes | AF1: Doubts/Questions
A2: Unique ID | B2: =COUNTA(_xlfn.UNIQUE(B3:B677))-1 -> 82 | D2: Safety | E2: Built Environment | F2: Ambient Environment | G2: Housing | H2: Economic Development | I2: Social Infrastructure | J2: Sociodemographics | K2: Mobility & Transport | L2: =COUNTA(_xlfn.UNIQUE(L3:L677))-1 -> 18 | M2: =COUNTA(_xlfn.UNIQUE(M3:M677))-1 -> 30 | N2: =COUNTA(_xlfn.UNIQUE(N3:N677))-1 & " unique of " &COUNTA(N3:N677) -> 80 unique of 81 | O2: =COUNTA(_xlfn.UNIQUE(O3:O677))-1 -> 10 | P2: Proximity | Q2: Accessibility (threshold) | R2: Quantity (threshold) | S2: Density (threshold) | T2: Diversity | U2: Quality | W2: Citation(s) | X2: Effect size (signed measure and confidence interval/uncertainty if stated) | Y2: =COUNTA(_xlfn.UNIQUE(Y3:Y677))-1 -> 2 | Z2: =COUNTA(_xlfn.UNIQUE(Z3:Z677))-1 -> 5 | AA2: =COUNTA(_xlfn.UNIQUE(AA3:AA677))-1 -> 25 | AB2: =COUNTIF(AB3:AB84,"<>") & " (Number indicates duplicated indicator #)" -> 0 (Number indicates duplicated indicator #) | AC2: =COUNTA(_xlfn.UNIQUE(AC3:AC677))-1 -> 32 | AD2: =COUNTA(_xlfn.UNIQUE(AD3:AD677))-1 -> 19 | AE2: =COUNTA(_xlfn.UNIQUE(AE3:AE677))-1 -> 18 | AF2: =COUNTA(_xlfn.UNIQUE(AF3:AF677))-1 -> 28
A3: 289 | B3: Housing affordability | C3: Housing | G3: x | M3: Affordable Housing | N3: Housing affordability | O3: Accessibility; Equity 27: Quantity | Q3: x | R3: x | V3: Affordable housing is essential for liveability and health as high housing costs limit resources for other social determinants of health like food and healthcare. | W3: Saitluanga, 2014, 'Spatial pattern of urban livability in Himalayan region: a case of Aizawl City'; Porio, 2015, 'Sustainable development goals and quality of life targets: insights from metro Manila' | X3: Association reported; no effect size provided. | AA3: 22; 27 | AC3: 27: ['median housing cost relative to income'] 22: ['Percentage of land being used for informal housing'] | AD3: "con la ENIGH se puede calcular gasto de alquiler entre ingresos" https://www.inegi.org.mx/programas/enigh/nc/2024/ "Encuesta Nacional de Vivienda (ENVI) 2020" https://www.inegi.org.mx/programas/envi/2020/ " Tipología de vivienda (2024)" from the Actualizaciones del territorio maps https://www.mexicali.gob.mx/sitioimip/geovisor | AE3: ER: Data will only be available at the city-level from the "Encuesta Nacional de Vivienda (ENVI) 2020" https://www.inegi.org.mx/programas/envi/2020/ We could also use the categories from the " Tipología de vivienda (2024)" from the Actualizaciones del territorio maps https://www.mexicali.gob.mx/sitioimip/geovisor
A4: 290 | B4: =N4 -> Land and house price | C4: Housing | G4: x | M4: Affordable Housing | N4: Land and house price | O4: Quantity; Equity | R4: x | V4: High housing and land prices are linked to reduced affordability and financial stress, which can negatively impact residents' overall quality of life and residential stability. | W4: Liu et al., 2020, 'Using multi-source data to assess livability in Hong Kong at the community-based level: A combined subjective-objective approach' | X4: Association reported; no effect size provided. | AA4: 16 | AC4: 16: ['Exploratory Factor Analysis', 'Standard Deviational Ellipse,', 'Hot Spot Analysis,', 'Network Analysis'] | AD4: "con la ENIGH se puede calcular gasto de alquiler entre ingresos" https://www.inegi.org.mx/programas/enigh/nc/2024/ "Encuesta Nacional de Vivienda (ENVI) 2020" https://www.inegi.org.mx/programas/envi/2020/ " Tipología de vivienda (2024)" from the Actualizaciones del territorio maps https://www.mexicali.gob.mx/sitioimip/geovisor | AE4: ER: Juan, el catastro tiene costo del lote y vivienda? https://tecmx.sharepoint.com/:f:/s/Mexicali-SIUM/IgCo34MzoO2pQ6n_8_fN7n7yAXbMN8SNG9AALvIBr0s7taI?e=R4YpGb https://tecmx.sharepoint.com/:f:/s/Mexicali-SIUM/IgCIU9bPtEF1RI3-GeohnPsyAV8qQj9UYPAZZ3rpy6S1RZE?e=mcIQXk | AF4: CH: To judge what is "high" and unaffordable may require some interpretation / guidance / use of a threshold (in Australia we us a 30:40 measure of housing affordability stress https://www.ahuri.edu.au/analysis/brief/understanding-3040-indicator-housing-affordability-stress
A5: 293 | B5: =N5 -> Number of days with good air quality | C5: Ambient Environment | F5: x | L5: Risks | M5: Air Quality | N5: Number of days with good air quality | O5: Quantity | R5: x | V5: The frequency of days with high-quality air is a fundamental indicator of urban environmental health and atmospheric safety for residents. | W5: Estoque et al., 2019, 'A review of quality of life (QOL) assessments and indicators: Towards a "QOL-Climate" assessment framework'; Liang et al., 2020, 'Assessment of the impact of climate change on cities livability in China' | X5: Liveability score: weighted indicator, no individual effect size reported | AA5: 3; 31 | AC5: 3: ['Entropy TOPSIS model', 'Tobit model'] 31: ['Grey relational degree', 'Entropy-TOPSIS model'] | AD5: Official Air Quality monitoring system: https://www.mexicali.gob.mx/portalmexicali/calidad-aire/indices?id=1 Review historial data from this source
A6: 292 | B6: =N6 -> Air quality | C6: Ambient Environment | F6: x | L6: Risks | M6: Air Quality | N6: Air quality | O6: Quality | U6: x | V6: Better air quality prioritizes physical health and promotes overall well-being by reducing exposure to harmful atmospheric pollutants. | W6: Wang et al., 2011, 'A Comparative Study of Beijing and Three Global Cities: A Perspective on Urban Livability'; Mahmud et al., 2020, 'Assessment of Groundwater Quality in Khulna City of Bangladesh in Terms of Water Quality Index for Drinking Purpose' | X6: Association reported; no effect size provided. | Y6: 2 | AA6: 18;22 | AC6: 1: ['Delphi', "Kendall's coefficient", "Cronbach's alpha value"] 6: ['Delphi Process', 'Analytic Hierarchy Process'] 18: ['Analytic Hierarchy Process (AHP)'] 22: ['N/A'] | AD6: Official Air Quality monitoring system: https://www.mexicali.gob.mx/portalmexicali/calidad-aire/indices?id=1 | AF6: ER: Too broad (should be defined by particles)?
A7: 8 | B7: =N7 -> Good air quality | C7: Ambient Environment | F7: x | L7: Risks | M7: Air Quality | N7: Good air quality | O7: Quality | U7: x | V7: Suitable air quality is a fundamental environmental requirement for reducing risks of respiratory and cardiovascular diseases in urban populations. | W7: Yang et al., 2021, 'Spatiotemporal trends and driving factors of urban livability in the Yangtze River Delta Agglomeration'; Zhu et al., 2021, 'Enhancing and promoting national environmental goals through local integrated coastal management initiatives and legislation' | X7: Association reported; no effect size provided. | AA7: 16 | AC7: ['Exploratory Factor Analysis', 'Standard Deviational Ellipse,', 'Hot Spot Analysis,', 'Network Analysis'] | AD7: Official Air Quality monitoring system: https://www.mexicali.gob.mx/portalmexicali/calidad-aire/indices?id=1
A8: 136 | B8: =N8 -> Annual average nitrogen dioxide (1-e6 mmol/m²) | C8: Ambient Environment | F8: x | L8: Risks | M8: Air Quality | N8: Annual average nitrogen dioxide (1-e6 mmol/m²) | O8: Quantity; Quality | R8: x | U8: x | V8: Nitrogen dioxide is identified as a major urban problem impacting health and wellbeing, with high concentrations linked to respiratory and cardiovascular issues. | W8: Lowe et al., 2015, 'Planning healthy, liveable and sustainable cities: how can indicators inform policy?'; Badland et al., 2014, 'Urban liveability: emerging lessons from Australia for exploring the potential for indicators to measure the social determinants of health' | X8: Association reported; no effect size provided. | Y8: 1 | AA8: 13 | AC8: ['Identification of measurable spatial indicators, how they can me calculated and monitored'] | AD8: Sentinel-5P NRTI NO2: Near Real-Time Nitrogen Dioxide (https://developers.google.com/earth-engine/datasets/catalog/COPERNICUS_S5P_NRTI_L3_NO2?hl=es-419)
A9: 173 | B9: =N9 -> Number of days PM 2.5 exceeds WHO standard (25 µg/m³) | C9: Ambient Environment | F9: x | L9: Risks | M9: Air Quality | N9: Number of days PM 2.5 exceeds WHO standard (25 µg/m³) | O9: Quantity | R9: x | V9: Monitoring PM2.5 levels relative to international WHO standards ensures that the city is tracking environmental risks that impact population cardiovascular and respiratory health. | W9: Lowe et al., 2015, 'Planning healthy, liveable and sustainable cities: how can indicators inform policy?'; Badland et al., 2014, 'Urban liveability: emerging lessons from Australia for exploring the potential for indicators to measure the social determinants of health' | X9: Association reported; no effect size provided. | AA9: 13 | AC9: ['Identification of measurable spatial indicators, how they can me calculated and monitored'] | AD9: Official Air Quality monitoring system: https://www.mexicali.gob.mx/portalmexicali/calidad-aire/indices?id=1 Review historial data from this source
A10: 252 | B10: =N10 -> Per capita SO2 emissions | C10: Ambient Environment | F10: x | L10: Risks | M10: Air Quality | N10: Per capita SO2 emissions | O10: Quantity | R10: x | V10: Lower levels of sulfur dioxide emissions signify reduced industrial pollution and progress toward carbon reduction, which are necessary for a sustainable living environment. | W10: Estoque et al., 2019, 'A review of quality of life (QOL) assessments and indicators: Towards a "QOL-Climate" assessment framework'; Liang et al., 2020, 'Assessment of the impact of climate change on cities livability in China' | X10: Liveability score: weighted indicator, no individual effect size reported | AA10: 31, 3 | AC10: 3: ['Entropy TOPSIS model', 'Tobit model'] 31:['Grey relational degree', 'Entropy-TOPSIS model'] | AE10: ER: Review if there is available data from SEMARNAT for: Bióxido de azufre (SO2) "We could potentially use data from: Registro de Emisiones y Transferencias de Contaminantes (RETC) 2004-2024 (https://sinat.semarnat.gob.mx:8443/retc/retc/index.php) or Taking Stock on industry (https://takingstock.cec.org/Map?IndustryLevel=4&Measure=3&MediaTypes=2&ReportType=1&ResultType=1&Years=2023)"
A11: 19 | B11: =N11 -> Building design | C11: Built Environment | E11: x | L11: Urban Morphology | M11: Buildings | N11: Building design | O11: Quantity | R11: x | V11: Building morphology and arrangement are critical for housing quality and social interaction, supporting healthy environments through improved urban ventilation. | W11: Chan & Liu, 2018, 'Effects of neighborhood building density, height, greenspace, and cleanliness on indoor environment and health'; Ramponi & Blocken, 2012, 'A computational study on the influence of urban morphology on wind-induced outdoor ventilation'; Yuan & Ng, 2012, 'Building porosity for better urban ventilation' | X11: Association reported; no effect size provided. | AA11: 23 | AC11: ['Design Analysis', 'Airflow simulations'] | AF11: I am not sure we can obtain data for this
A12: 22 | B12: =N12 -> Building height | C12: Built Environment | E12: x | L12: Urban Morphology | M12: Buildings | N12: Building height | O12: Quantity | R12: x | V12: Variation in building heights within a neighbourhood improves natural ventilation and passive pollutant dispersion while supporting residential privacy and safety. | W12: Ng, 2010, 'Designing high density cities for social & environmental sustainability'; An et al., 2019, 'Exploration of sustainable building morphologies for effective passive pollutant dispersion' | X12: Association reported; no effect size provided. | AA12: 23 | AC12: ['Design Analysis', 'Airflow simulations'] | AF12: ER: Can we calculate this with OpenBuildings?
A13: 1 | B13: =N13 -> Public services | C13: Social Infrastructure | I13: x | L13: Public Services | M13: Community Facilities | N13: Public services | O13: Accessibility | Q13: 500 | U13: x | V13: Access to telecommunication infrastructure and mobile network coverage is identified as a vital public service and a major interest for resident liveability. | W13: Atkisson & Hatcher, 2001, 'The compass index of sustainability'; Valentin & Spangenberg, 2000, 'A guide to community sustainability indicators' | X13: Liveability score: weighted indicator, no individual effect size reported | AA13: 8 | AC13: ['Hierarchical Modelling using Analytic Hierarchy Process (AHP)'] | AF13: CH: is there much variation in access to telecommunications infrastructure in mexicali?
A14: 46 | B14: ="Access to "&LOWER(N14) -> Access to community centres | C14: Social Infrastructure | I14: x | L14: Community, culture & leisure | M14: Community Facilities | N14: Community centres | O14: Accessibility | P14: x | Q14: 500 | R14: x | S14: x | V14: Multi-purpose community centres provide important opportunities for social interaction and community connection, which are vital for mental and social wellbeing. | W14: Saitluanga, 2014, 'Spatial pattern of urban livability in Himalayan region: a case of Aizawl City' | X14: Association reported; no effect size provided. | Y14: 1 | Z14: Destination analysis using GHSCI tools with permutations of: distance to closest, access within threshold(s), and where applicable count per sqkm and per 1,000 persons | AA14: 22 | AC14: ['Percentage of residents living < 400 m of community centre'] | AD14: OSM/ DENUE/IMIP
A15: 394 | B15: ="Access to "&LOWER(N15) -> Access to youth centres | C15: Social Infrastructure | I15: x | L15: Community, culture & leisure | M15: Community Facilities | N15: Youth centres | O15: Quantity | P15: x | Q15: 500 | R15: x | S15: x | V15: Access to youth centres provides essential social infrastructure that supports social cohesion, mental health, and community wellbeing for young residents. | W15: Lowe et al., 2015, 'Planning healthy, liveable and sustainable cities: how can indicators inform policy?' | X15: Association reported; no effect size provided. | Z15: Destination analysis using GHSCI tools with permutations of: distance to closest, access within threshold(s), and where applicable count per sqkm and per 1,000 persons | AA15: 13 | AC15: ['Identification of measurable spatial indicators, how they can me calculated and monitored'] | AD15: OSM/ DENUE/IMIP
A16: 11 | B16: ="Access to "&LOWER(N16) -> Access to bakery | C16: Economic Development | H16: x | I16: x | L16: Food Environment | M16: Convenience Destinations | N16: Bakery | O16: Quantity | P16: x | Q16: 500 | R16: x | S16: x | V16: The presence of local bakeries and food services contributes to the convenience of urban life and supports the everyday functional needs of residents. | W16: Ghasemi, 2024, 'Enhancing urban livability: Analyzing Tehran through equitable land use distribution' | X16: Association reported; no effect size provided. | Z16: Destination analysis using GHSCI tools with permutations of: distance to closest, access within threshold(s), and where applicable count per sqkm and per 1,000 persons | AA16: 16 | AC16: ['Exploratory Factor Analysis', 'Standard Deviational Ellipse,', 'Hot Spot Analysis,', 'Network Analysis'] | AD16: OSM/ DENUE/IMIP | AE16: CH: Probably should be grouped with other convenience destinations/ ER: Agreed, but particulary with those food-related, maybe part of a food environment comoposite index?
A17: 129 | B17: ="Access to "&LOWER(N17) -> Access to markets | C17: Economic Development | H17: x | I17: x | L17: Food Environment | M17: Convenience Destinations | N17: Markets | O17: Quantity | P17: x | Q17: 500 | R17: x | S17: x | V17: Local markets provide residents with access to fresh food and opportunities for economic activity and social interaction within their neighborhoods. | W17: Ghasemi, 2024, 'Enhancing urban livability: Analyzing Tehran through equitable land use distribution'; Yang et al., 2021, 'Spatiotemporal trends and driving factors of urban livability in the Yangtze River Delta Agglomeration' | X17: Association reported; no effect size provided. | Z17: Destination analysis using GHSCI tools with permutations of: distance to closest, access within threshold(s), and where applicable count per sqkm and per 1,000 persons | AA17: 16 | AC17: ['Exploratory Factor Analysis', 'Standard Deviational Ellipse,', 'Hot Spot Analysis,', 'Network Analysis'] | AD17: OSM/ DENUE/IMIP | AF17: ER: This one can be part of a composite sub-index
A18: 132 | B18: ="Access to "&LOWER(N18) -> Access to minimarts | C18: Economic Development | H18: x | L18: Food Environment | M18: Convenience Destinations | N18: Minimarts | O18: Quantity | P18: x | Q18: 500 | R18: x | S18: x | V18: The availability of minimarts is an indicator of local food access, supporting the convenient provision of daily necessities that shape urban life quality. | W18: Lowe et al., 2015, 'Planning healthy, liveable and sustainable cities: how can indicators inform policy?'; Alderton et al., 2019, 'What is the meaning of urban liveability for a city in a low-to-middle-income country? Contextualising liveability for Bangkok, Thailand' | X18: Association reported; no effect size provided. | Z18: Destination analysis using GHSCI tools with permutations of: distance to closest, access within threshold(s), and where applicable count per sqkm and per 1,000 persons | AA18: 13 | AC18: ['Identification of measurable spatial indicators, how they can me calculated and monitored'] | AD18: OSM/ DENUE/IMIP | AE18: CH: worth noting, minimarts may not be 'healthy food' necessarily (depends on context how its interpreted -- eg is OXXO a healthy food destination? maybe more associated with junk/convenience food?)
A19: 232 | B19: ="Access to "&LOWER(N19) -> Access to restaurants | C19: Economic Development | H19: x | I19: x | L19: Food Environment | M19: Convenience Destinations | N19: Restaurants | O19: Quantity | P19: x | Q19: 500 | R19: x | S19: x | V19: Restaurants contribute to the recreational diversity of urban districts, offering spaces for socialization and enhancing the vibrancy of the neighborhood. | W19: Ghasemi, 2024, 'Enhancing urban livability: Analyzing Tehran through equitable land use distribution'; Kang et al., 2022, 'Can tourism development make cities more livable? Investigating 40 cities in China' | X19: Association reported; no effect size provided. | Z19: Destination analysis using GHSCI tools with permutations of: distance to closest, access within threshold(s), and where applicable count per sqkm and per 1,000 persons | AA19: 16 | AC19: ['Exploratory Factor Analysis', 'Standard Deviational Ellipse,', 'Hot Spot Analysis,', 'Network Analysis'] | AD19: OSM/ DENUE
A20: 367 | B20: ="Access to "&LOWER(N20) -> Access to supermarket | C20: Economic Development | H20: x | I20: x | L20: Food Environment | M20: Convenience Destinations | N20: Supermarket | O20: Quantity | P20: x | Q20: 500 | R20: x | S20: x | V20: The availability of supermarkets is a indicator of the formal food environment that influences residents' ability to access varied and nutritional food options. | W20: Lowe et al., 2015, 'Planning healthy, liveable and sustainable cities: how can indicators inform policy?' | X20: Association reported; no effect size provided. | Z20: Destination analysis using GHSCI tools with permutations of: distance to closest, access within threshold(s), and where applicable count per sqkm and per 1,000 persons | AA20: 13 | AC20: ['Identification of measurable spatial indicators, how they can me calculated and monitored'] | AD20: OSM/ DENUE | AE20: Worth measuring access to supermarkets in a number of different ways (distance, count, within threshold) as required | AF20: ER: Review the composite hierarchy number
A21: 169 | B21: ="Access to "&LOWER(N21) -> Access to petrol station (>= 250m away) | C21: Economic Development | H21: x | L21: Resources | M21: Convenience Destinations | N21: Petrol station (>= 250m away) | O21: Proximity | P21: x | Q21: >=250m | R21: x | S21: x | V21: Living at a sufficient distance from gas stations improves residents' safety by reducing the risks of fire incidents and accidents associated with hazardous fuel locations. | W21: Basu et al., 2021, 'Urban Livability Index Assessment Based on Land-Use Changes in an Indian Medium-Sized City (Raiganj)' | X21: Association reported; no effect size provided. | Z21: Destination analysis using GHSCI tools with permutations of: distance to closest, access within threshold(s), and where applicable count per sqkm and per 1,000 persons | AA21: 18 | AC21: ['Analytic Hierarchy Process (AHP)'] | AD21: OSM/ DENUE/IMIP (abasto layer) https://www.mexicali.gob.mx/sitioimip/geovisor/geovisor/?url=act-terr&access_token= | AE21: CH: the evidence for this one might be complex -- I can imagine there might be a sweet spot --- yes, you don't want to be too close (how close is that, maybe that is our indicator --- not within XXX distance m, if we can link with citable evidence.) But the reality is people do drive, and need petrol or perhaps electrical charging; living too far from one could impact some aspects of life. Lets be guided by evidence here. Here's a good basis for an indicator: Petrol station within 250m is associated with increased relative risk of childhood leukemia. Another study: https://link.springer.com/article/10.1007/s00420-021-01767-y
A22: 296 | B22: =N22 -> Crime? | C22: Safety | D22: x | L22: Personal Safety | M22: Crime | N22: Crime? | O22: Accessibility | Q22: x | V22: Personal safety and the reduction of urban risk through protective infrastructure are identified as fundamental requirements for city liveability and resident well-being. | W22: Mercer, 2017, 'Quality of Living Survey'; Economist Intelligence Unit (EIU), 2012, 'Quality of Life Index' | X22: Liveability score: weighted indicator, no individual effect size reported | AA22: 8 | AC22: ['Hierarchical Modelling using Analytic Hierarchy Process (AHP)'] | AF22: CH: Only useful if it can be acquired with meaningful variation
A23: 121 | B23: ="Access to "&LOWER(N23) -> Access to libraries | C23: Social Infrastructure | I23: x | L23: Community, culture & leisure | M23: Culture & Leisure | N23: Libraries | O23: Proximity | P23: x | Q23: 1000 | R23: x | S23: x | V23: Easy access to cultural facilities like libraries is a key component of urban convenience, allowing residents to satisfy their fundamental information and educational requirements. | W23: Onnom et al., 2018, 'Development of a Liveable City Index (LCI) Using Multi Criteria Geospatial Modelling for Medium Class Cities in Developing Countries'; Liu et al., 2020, 'Using Multi-Source Data to Assess Livability in Hong Kong at the Community-Based Level: A Combined Subjective-Objective Approach' | X23: Association reported; no effect size provided. | Z23: Destination analysis using GHSCI tools with permutations of: distance to closest, access within threshold(s), and where applicable count per sqkm and per 1,000 persons | AA23: 18 | AC23: ['Analytic Hierarchy Process (AHP)'] | AD23: OSM/ DENUE/IMIP
A24: 228 | B24: ="Access to "&LOWER(N24) -> Access to religious buildings | C24: Social Infrastructure | I24: x | L24: Community, Culture & Leisure | M24: Culture & Leisure | N24: Religious buildings | O24: Proximity | P24: x | Q24: 500 | R24: x | S24: x | V24: Access to religious centres contributes to the amenity value of urban areas, providing social and cultural comfort that enhances human wellbeing. | W24: Rehdanz and Maddison, 2008, 'Local environmental quality and life-satisfaction in Germany' | X24: Association reported; no effect size provided. | Z24: Destination analysis using GHSCI tools with permutations of: distance to closest, access within threshold(s), and where applicable count per sqkm and per 1,000 persons | AA24: 20 | AC24: ['Proximity analysis following digitization and Euclidean distance computation'] | AD24: OSM/ DENUE/IMIP
A25: 58 | B25: ="Access to "&LOWER(N25) -> Access to cultural centers | C25: Social Infrastructure | I25: x | L25: Community, culture & leisure | M25: Culture & Leisure | N25: Cultural centers | O25: Quantity | P25: x | Q25: 1000 | R25: x | S25: x | V25: Cultural centers serve as important hubs for social and cultural activities that enhance community identity and promote the psychological well-being of residents. | W25: Kang et al., 2022, 'Can tourism development make cities more livable? Investigating 40 cities in China' | X25: Association reported; no effect size provided. | Z25: Destination analysis using GHSCI tools with permutations of: distance to closest, access within threshold(s), and where applicable count per sqkm and per 1,000 persons | AA25: 16 | AC25: ['Exploratory Factor Analysis', 'Standard Deviational Ellipse,', 'Hot Spot Analysis,', 'Network Analysis'] | AD25: OSM/ DENUE/IMIP | AF25: ER: This can be part of a "City amenities" composite index
A26: 134 | B26: ="Access to "&LOWER(N26) -> Access to museums | C26: Social Infrastructure | I26: x | L26: Community, culture & leisure | M26: Culture & Leisure | N26: Museums | O26: Quantity | P26: x | Q26: 1000 | R26: x | S26: x | V26: Museums provide important cultural infrastructure that supports social development, lifelong learning, and community social cohesion. | W26: Lowe et al., 2015, 'Planning healthy, liveable and sustainable cities: how can indicators inform policy?' | X26: Association reported; no effect size provided. | Z26: Destination analysis using GHSCI tools with permutations of: distance to closest, access within threshold(s), and where applicable count per sqkm and per 1,000 persons | AA26: 13 | AC26: ['Identification of measurable spatial indicators, how they can me calculated and monitored'] | AD26: OSM/ DENUE/IMIP | AF26: ER: This can be part of a "City amenities" composite index
A27: 61 | B27: =N27 -> Cycling infrastructure | C27: Mobility & Transport | K27: x | L27: Active Travel | M27: Cycling infrastructure | N27: Cycling infrastructure | O27: Accessibility | Q27: x | V27: Dedicated cycling infrastructure encourages sustainable, eco-friendly transportation and promotes physical health through regular active mobility. | W27: Mekuria et al., 2017, 'Improving Liveability Using Green and Active Modes'; Stehlin, 2014, 'Regulating inclusion: Spatial form, social process, and the normalization of cycling practice in the USA'; Ruggeri, 2013, 'From Transit Stop to Urbanity Node'; Whitney et al., 2020, 'Livable streets and global competitiveness: A survey of Mexico City' | X27: Compliance rate: 85.7% of evaluated liveability indices in the studied communities were related to public transport and green space availability. | AA27: 27 | AD27: IMIP: https://www.mexicali.gob.mx/sitioimip/geovisor/geovisor/?url=pimus&access_token= | AE27: CH: This sounds like a suite of indicators/ ER: Agreed, we could use the cycling indicators we have generating for this
A28: 338 | B28: =N28 -> Dwelling density | C28: Sociodemographics | J28: x | L28: Household | M28: Demographics | N28: Dwelling density | O28: Density | S28: x | V28: Appropriate household density within dwelling units is key to preventing the negative social and health consequences of urban overcrowding. | W28: Reynolds-Salmon et al., 2024, 'Does household size matter? Crowding and its effects on child development' | X28: Association reported; no effect size provided. | AA28: 16; 27; | AC28: 16: ['Exploratory Factor Analysis', 'Standard Deviational Ellipse,', 'Hot Spot Analysis,', 'Network Analysis'] 27: indicating the number of housing units per acre | AD28: INEGI Census
A29: 340 | B29: =N29 -> Population density | C29: Sociodemographics | J29: x | L29: City | M29: Demographics | N29: Population density | O29: Density | S29: x | V29: Excessive population density in fragile environments increases resource consumption and environmental stress, which can degrade the long-term liveability of a city. | W29: Chen et al., 2020, 'Response of resources and environment carrying capacity under the evolution of land use structure in Chongqing Section of the Three Gorges Reservoir Area'; Dong et al., 2021, 'The coupling coordinated relationship between new-type urbanization, eco-environment and its driving Mechanism: A case of Guanzhong, China' | X29: Urban liveability: β = -0.041 (p < 0.01), inverse association | AA29: 3; 8; 19; 27 | AC29: 3: ['Entropy TOPSIS model', 'Tobit model'] 8: ['Hierarchical Modelling using Analytic Hierarchy Process (AHP)'] 19: ['machine learning is integrated into semantic image segmentation technique to extract green pixels from the street view images using the scene parsing method; SVG', 'entropy index (relative percentage of various land-use types)'] 27: [GIS mapping] | AD29: INEGI Census | AG29: * Indicator categoy Demographics & subdomain city
A30: 112 | B30: =N30 -> Jobs | C30: Economic Development | H30: x | M30: Employment | N30: Jobs | O30: Quantity; Presence | R30: x | V30: Local employment opportunities allow residents to live and work within the same district, improving work-life balance and reducing the health burdens of long commutes. | W30: Saitluanga, 2014, 'Spatial pattern of urban livability in Himalayan region: a case of Aizawl City' | X30: Association reported; no effect size provided. | AA30: 22 | AC30: ['Percentage of residents living and working in the same district'] | AE30: Pues sí uno tiene El valor de fuerza laboral sería mejor con ese y El cociente sobre los que pueden trabajar
A31: 325 | B31: =N31 -> Fire incidence rate by population | C31: Ambient Environment; Safety | D31: x | F31: x | L31: Risks | M31: Fire | N31: Fire incidence rate by population | O31: Quantity | R31: x | V31: Fire safety, measured by the occurrence rate in the population, is a critical component of urban security, essential for protecting lives and property. | W31: Arpan & Joy, 2018, 'Livability assessment within a metropolis based on the impact of integrated urban geographic factors (IUGFs) on clustering urban centers of Kolkata'; Zhan et al., 2018, 'Assessment and determinants of satisfaction with urban livability in China' | X31: No health outcome assessed. | Y31: 2 | AA31: 17 | AC31: ['Not specified'] | AE31: ER: In Mexicali the Risk Atlas states that the most relevant fires are those related to industry, however, there is no data available for these.
A32: 71 | B32: =N32 -> Flooding | C32: Ambient Environment | F32: x | L32: Risks | M32: Flooding | N32: Flooding | O32: Accessibility | R32: x | V32: Mitigating the exposure and impact of urban flooding is essential for maintaining residents' health and safety, particularly for those in informal and vulnerable housing. | W32: No external citations provided for this indicator. | X32: No health outcome assessed. | Y32: 1 | AA32: 22 | AC32: ['N/A'] | AD32: Risk Atlas layers for Mexicali (https://www.mexicali.gob.mx/sitioimip/geovisor/geovisor/?geovisor_id=2&access_token=)
A33: 326 | B33: =N33 -> Flooding - annual average days for main roads | C33: Ambient Environment | F33: x | L33: Risks | M33: Flooding | N33: Flooding - annual average days for main roads | O33: Quantity | R33: x | V33: The duration of flooding in main road areas contributes to environmental risks and disruption of essential services, which can impact public health and safety. | W33: Parise, 2018, 'A brief review of global climate change and the public health consequences' | X33: Association reported; no effect size provided. | Y33: 2 | AA33: 13 | AC33: ['Identification of measurable spatial indicators, how they can me calculated and monitored']
A34: 72 | B34: =N34 -> Flooding - main roads | C34: Ambient Environment | F34: x | L34: Risks | M34: Flooding | N34: Flooding - main roads | O34: Quantity | R34: x | V34: The number of flood-prone locations on main roads is an indicator of infrastructure vulnerability that directly affects environmental safety and health risk management. | W34: Parise, 2018, 'A brief review of global climate change and the public health consequences' | X34: Association reported; no effect size provided. | Y34: 1 | AA34: 13 | AC34: ['Identification of measurable spatial indicators, how they can me calculated and monitored'] | AD34: Risk Atlas layers for Mexicali (https://www.mexicali.gob.mx/sitioimip/geovisor/geovisor/?geovisor_id=2&access_token=)
A35: 170 | B35: ="Access to "&LOWER(N35) -> Access to pharmacies | C35: Social Infrastructure | I35: x | L35: Health & Healthcare | M35: Health & Social Services | N35: Pharmacies | O35: Density | P35: x | Q35: 1000 | R35: x | S35: per 1000 persons | V35: Access to medical stores is identified by residents as a fundamental amenity for liveability, ensuring the availability of healthcare commodities across the city. | W35: Chi et al., 2021, 'From Comparative and Statistical Assessments of Liveability and Health Conditions of Districts in Hong Kong towards Future City Development'; Suptelo & Sehida, 2020, 'Factors of Post-Industrial Transformations of Urban Sociogeosystems (Case Kharkiv)' | X35: Amenity accessibility: association reported; no individual effect size provided. | Z35: Destination analysis using GHSCI tools with permutations of: distance to closest, access within threshold(s), and where applicable count per sqkm and per 1,000 persons | AA35: 5 | AC35: ['Supervised classification in Erdas Imagine Software.', 'regression'] | AD35: OSM/ DENUE/IMIP
A36: 97 | B36: ="Access to "&LOWER(N36) -> Access to health centres | C36: Social Infrastructure | I36: x | L36: Health & Healthcare | M36: Health & Social Services | N36: Health centres | O36: Proximity | P36: x | Q36: 1000 | R36: x | S36: x | V36: Proximity to healthcare facilities is essential for maintaining urban life quality and ensures residents have timely access to medical services. | W36: McMichael, 2000, 'The urban environment and health in a world of increasing globalisation: issues for developing countries' | X36: Association reported; no effect size provided. | Z36: Destination analysis using GHSCI tools with permutations of: distance to closest, access within threshold(s), and where applicable count per sqkm and per 1,000 persons | AA36: 19; 20 | AC36: 19: ['machine learning is integrated into semantic image segmentation technique to extract green pixels from the street view images using the scene parsing method; SVG', 'entropy index (relative percentage of various land-use types)'] 20: ['Proximity analysis following digitization and Euclidean distance computation'] | AD36: OSM/ DENUE/IMIP | AE36: I would make this distance to General Practitioner / local health centre
A37: 101 | B37: ="Access to "&LOWER(N37) -> Access to hospitals | C37: Social Infrastructure | I37: x | L37: Health & Healthcare | M37: Health & Social Services | N37: Hospitals | O37: Quantity; Presence | P37: x | Q37: 2000 | R37: x | S37: x | V37: The physical availability and accessibility of healthcare facilities, such as hospitals, are essential determinants of health within the urban liveability framework. | W37: Mercer, 2017, 'Quality of Living Survey'; Economist Intelligence Unit (EIU), 2012, 'Quality of Life Index' | X37: Liveability score: weighted indicator, no individual effect size reported | Z37: Destination analysis using GHSCI tools with permutations of: distance to closest, access within threshold(s), and where applicable count per sqkm and per 1,000 persons | AA37: 8 | AC37: ['Hierarchical Modelling using Analytic Hierarchy Process (AHP)'] | AD37: OSM/ DENUE/IMIP | AE37: I would make this distance to hospital (as distinct from distance to GP)
A38: 382 | B38: =N38 -> Urban heat island | C38: Ambient Environment | F38: x | L38: Risks | M38: Heat | N38: Urban heat island | O38: Quantity | R38: x | V38: Mitigating the urban heat island effect by reducing localized temperature increases promotes thermal comfort and supports the physical and mental well-being of city dwellers. | W38: Leya et al., 2022, 'Spatial Variations of Urban Heat Island Development in Khulna City, Bangladesh: Implications for Urban Planning and Development' | X38: Association reported; no effect size provided. | AA38: 18 | AC38: ['Analytic Hierarchy Process (AHP)'] | AF38: ER: Key indicator
A39: 127 | B39: ="Access to "&LOWER(N39) -> Access to manufacturing district / centre | C39: Economic Development | H39: x | L39: Economy | M39: Industry; Employment | N39: Manufacturing district / centre | O39: Proximity | P39: x | Q39: ? | R39: x | S39: x | V39: Manufacturing centres are sources of industrial hazards and pollution; restricting residential proximity ensures physical safety and protects wellbeing. | W39: Onnom et al., 2018, 'Development of a Liveable City Index (LCI) using multi criteria geospatial modelling for medium class cities in developing countries' | X39: Association reported; no effect size provided. | Z39: Destination analysis using GHSCI tools with permutations of: distance to closest, access within threshold(s), and where applicable count per sqkm and per 1,000 persons | AA39: 20 | AC39: ['Proximity analysis following digitization and Euclidean distance computation'] | AD39: DENUE | AE39: CH: we need to provide clear evidence/guidance about what this means (e.g. is proximity good because of employment opportunities, or bad because of exposure to air/noise pollution?) | AF39: ER: High relevance as Condesa haz manufacturing facilities.
A40: 405 | B40: =N40 -> Land use type | C40: Ambient Environment | F40: x | L40: Resources | M40: Land | N40: Land use type | O40: Quality | U40: x | AA40: 28 | AD40: https://www.mexicali.gob.mx/sitioimip/geovisor/geovisor/?url=pducpmp&access_token= IMIP: usos de suelo https://tecmx.sharepoint.com/:f:/s/Mexicali-SIUM/IgCeSV3JIwQpT6TXm52Vw2gqAXN8KTu7Dex3TtPfbb754oo?e=4QOX5y | AF40: ER: Could be used to calculate land use mix
...

Sheet Lens - Enfoque
A1: Lens / Enfoque (plural approaches for considering an indicator) | B1: Reference | C1: Description of analytical lens | D1: Indicator example (e.g. aggregate for manzanas / AGEB / grid, as appropriate/feasible) | E1: Example reference
A2: Proximity | B2: Network distance | C2: Distance to closest (m) along the pedestrian network | D2: Average distance to the closest blue space (m)
A3: Accessibility | B3: Within threshold distance | C3: Access within relevant threshold | D3: Percentage of population who can access a blue space within threshold distances (<300m; 300-600m; 600-1200m; 1200-1500m;>1500m)
A4: Quantity | B4: Within area or threshold | C4: Count within relevant threshold | D4: Count of blue spaces within threshold distances (<300m; 300-600m; 600-1200m; 1200-1500m;>1500m)
A5: Density | B5: Within area or threshold | C5: Relative to another unit (e.g. sqkm or per capita), or percentage coverage | D5: Percentage of blue space within neighbourhood
D6: Supermarkets per km2
D7: Square meters of green space per capita
A8: Diversity | B8: Within area or threshold | C8: Entropy score (is what I think of) | D8: Land use mix | E8: Mavoa, S., Eagleson, S., Badland, H. M., Gunn, L., Boulange, C., Stewart, J., & Giles-Corti, B. (2018). Identifying appropriate land-use mix measures for use in a national walkability index. Journal of Transport and Land Use, 11(1). https://doi.org/10.5198/jtlu.2018.1132
A9: Quality | B9: Depends? | D9: >= 9sqm green space per capita within 15 minutes walking distance | E9: https://unhabitat.org/developing-public-space-and-land-values-in-cities-and-neighbourhoods

Sheet Article list
A1: Article # | B1: title | C1: Author | D1: Year | E1: Search | F1: Notas | G1: Extra relevant | H1: Excluded
A2: 1 | B2: A methodology for the identification of significant factors for the improvement of pedestrian facilities in an urban area | C2: Aromal | D2: 2021 | E2: 1 | F2: This article's main aim is to develop a comprehensive list of factors that would help in the decision-making process for the improvement of pedestrian facilities in urban areas. It includes built environment factors related to liveability and in fact a domain they call Ambience/Liveability. Should we keep it? | H2: 2026-07-17 ER JN CH discussion (doesn't meet inclusion / exclusion criteria)
A3: 2 | B3: A sustainability assessment framework for population density in central Indian cities | C3: Kamble | D3: 2021 | E3: 1 | F3: Not focused on liveability | H3: Excluded
A4: 3 | B4: Assessment and key factors of urban liveability in underdeveloped regions: A case study of the Loess Plateau, China | C4: Xiao | D4: 2022 | E4: 1
A5: 4 | B5: Can Tourism Development Make Cities More Livable? Investigating 40 Cities in China | C5: Kang | D5: 2022 | E5: 1,2,3 | H5: 2026-07-17 ER JN CH discussion (doesn't meet inclusion / exclusion criteria)
A6: 5 | B6: Constructing a city liveability index and evaluating the spatial pattern of liveability of Guwahati city | C6: Mahanta | D6: 2025 | E6: 1
A7: 6 | B7: Decision-Making Framework for Prioritizing the Improvement of Pedestrian Facilities in Urban Areas Using Integrated Delphi, AHP, and TOPSIS Approach | C7: Aromal | D7: 2022 | E7: 1 | F7: Not focused on liveability | H7: Excluded
A8: 7 | B8: Determining Factors Influencing Residents’ Satisfaction Regarding Urban Livability in Pakistan | C8: Baig | D8: 2019 | E8: 1 | F8: This study ONLY uses survey data | H8: 2026-07-17 ER JN CH discussion (doesn't meet inclusion / exclusion criteria)
A9: 8 | B9: Development of a Liveable City Index (LCI) Using Multi Criteria Geospatial Modelling for Medium Class Cities in Developing Countries | C9: Onnom | D9: 2018 | E9: 1 | G9: *
A10: 9 | B10: Infill Architecture as a Solution for Livability and Historical Texture Quality Promotion | C10: Beiglu | D10: 2019 | E10: 1 | F10: This article is more conceptual, it does have a section on liveability and includes some measures but without detail on how these are calculated | H10: 2026-07-17 ER JN CH discussion (doesn't meet inclusion / exclusion criteria)
A11: 10 | B11: Investigation of Urban Design Approaches in Renewal Areas with Hybrid Decision Model | C11: Gungor | D11: 2022 | E11: 1 | F11: Not focused on liveability | H11: Excluded
A12: 11 | B12: Livability in dense residential neighbourhoods of Dhaka | C12: Satu | D12: 2019 | E12: 1 | F12: This study ONLY uses survey data | H12: 2026-07-17 ER JN CH discussion (doesn't meet inclusion / exclusion criteria)
A13: 12 | B13: Measuring Liveability by Exploring Urban Qualities of Kissy Street, Freetown, Sierra Leone | C13: Conteh | D13: 2016 | E13: 1
A14: 13 | B14: Measuring and monitoring liveability in a low-to-middle income country: a proof-of-concept for Bangkok, Thailand and lessons from an international partnership | C14: Alderton | D14: 2021 | E14: 1
A15: 14 | B15: Paying for the quality of life: The impacts of urban livability on CEO compensation | C15: Li | D15: 2021 | E15: 1 | F15: This study assesses if urban liveability is correlated with higher CEO compensation. Although is not focused on liverability, it does measure liveability as the independent variable | H15: 2026-07-17 ER JN CH discussion (doesn't meet inclusion / exclusion criteria); This article is not relevant as is not focused on the main population but only executives of listed companies;
A16: 15 | B16: Planning and designing livable recreational open spaces in developing countries. Insights from Souk Ahras City, Algeria | C16: Hafsi | D16: 2024 | E16: 1 | F16: This study investigated the role of urban planning and urban design in shaping livable recreational open spaces in Souk Ahras City, Algeria.
A17: 16 | B17: Spatial analysis and ranking of urban districts based on a comprehensive livability approach: the case of Tehran | C17: Kashi | D17: 2025 | E17: 1
A18: 17 | B18: The impact of economic development on urban livability: Evidence from 40 large and medium-sized cities of China | C18: Wang | D18: 2023 | E18: 1
A19: 18 | B19: Urban Livability in a Rapidly Urbanizing Mid-Size City: Lessons for Planning in the Global South | C19: Jodder | D19: 2024 | E19: 1
A20: 19 | B20: Urban greenness, mixed land-use, and life satisfaction: Evidence from residential locations and workplace settings in Beijing | C20: Wu | D20: 2022 | E20: 1 | F20: This study aims to provide insights into the interaction effect between neighbourhood greenness (proxied by eye-sensored street view exposure to greenspaces) and mixed land-use (measured by micro-level point-ofinterest entropy) in shaping residents’ life satisfaction (as an indicator of urban liveability).
A21: 20 | B21: Urban livability index assessment based on land-use changes in an Indian medium-sized city (Raiganj) | C21: Basu | D21: 2021 | E21: 1
A22: 21 | B22: Urban walkability assessment: methods and implications for city planning | C22: Chaudhary | D22: 2025 | E22: 1 | F22: Not focused on liveability | H22: Excluded
A23: 22 | B23: What is the meaning of urban liveability for a city in a low-to-middle-income country? Contextualising liveability for Bangkok, Thailand | C23: Alderton | D23: 2019 | E23: 1
A24: 23 | B24: Socio-physical liveability through socio-spatiality in low-income resettlement archetypes - A case of slum rehabilitation housing in Mumbai, India. | C24: Sarkar | D24: 2020 | E24: 3
A25: 24 | B25: Evaluating the impact of urban green spaces on public well-being and environmental sustainability in Saudi Arabian megacities | C25: Addas | D25: 2025 | E25: 3 | F25: Not focused on liveability | H25: Excluded
A26: 25 | B26: Urban green space in transition: A cross-continental perspective from eight Global North and South cities | C26: Derdoui | D26: 2025 | E26: 3 | F26: Not focused on liveability | H26: Excluded
A27: 26 | B27: Transforming Riyadh: urban development, quality of life, and spatial equity under Vision 2030 | C27: Mahboob | D27: 2025 | E27: 3
A28: 27 | B28: Integrated Framework for Enhancing Liveability and Ecological Sustainability in UAE Communities | C28: Alzaim | D28: 2024 | E28: 3
A29: 28 | B29: Evaluation of the livability of arid urban environments under global warming: A multi-parameter approach | C29: Chen | D29: 2023 | E29: 3 | G29: *
A30: 29 | B30: Setting up the ENVI-met digital tool to evaluate climatic conditions at an urban scale: a case study of Djelfa, Algeria | C30: Brahimi | D30: 2023 | E30: 3 | F30: Not focused on liveability | H30: Excluded
A31: 30 | B31: Transit-Oriented Development and Urban Livability in Gulf Cities: Comparative Analysis of Doha’s West Bay and Riyadh’s King Abdullah Financial District | C31: Mazzetto | D31: 2025 | E31: 3
A32: 31 | B32: Assessing spatial–temporal evolution and key factors of urban livability in arid zone: The case study of the Loess Plateau, China | C32: Xiao | D32: 2022 | E32: 3

Sheet Safety & Security
A1: Article # | B1: Excluded? | C1: Domain | D1: Subdomain | E1: Indicator / Category | F1: Subject | G1: Specific Measure lens / Enfoque | H1: Scale(s) | I1: Mexicali indicator | J1: Does it matter? | K1: Can we calculate this? Do we have data? | L1: What is the most pragmatic way of measuring it? | M1: Specific measures (from literature) | N1: Methods sub-indices/measures | O1: Notas | P1: Dudas
A2: 10 | B2: {=_xlfn.LET( _xlpm.ids, VALUE(_xlfn.TEXTSPLIT(SUBSTITUTE(A2,",",";"), ";", " ", TRUE)), _xlpm.status_list, _xlfn.MAP(_xlpm.ids, _xlfn.LAMBDA(_xlpm.id, _xlfn.LET( _xlpm.lookup_val, _xlfn.XLOOKUP(_xlpm.id, 'Article list'!$A$2:$A$995, 'Article list'!$H$2:$H$995, ""), AND(_xlpm.lookup_val <> "", _xlpm.lookup_val <> 0) ) )), _xlpm.total_count, COUNTA(_xlpm.ids), _xlpm.excluded_count, SUM(--_xlpm.status_list), _xlfn.IFS( _xlpm.excluded_count = _xlpm.total_count, TRUE, _xlpm.excluded_count = 0, FALSE, TRUE, "partial" ) )} -> TRUE | C2: Safety | D2: Personal Safety | E2: Public services | F2: ? | G2: quantity | M2: Security (Number of securing devices/arrangements) | N2: ['Fuzzy DEMATEL', 'Weighted Linear Combination (WLC),']
A3: 1 | B3: {=_xlfn.LET( _xlpm.ids, VALUE(_xlfn.TEXTSPLIT(SUBSTITUTE(A3,",",";"), ";", " ", TRUE)), _xlpm.status_list, _xlfn.MAP(_xlpm.ids, _xlfn.LAMBDA(_xlpm.id, _xlfn.LET( _xlpm.lookup_val, _xlfn.XLOOKUP(_xlpm.id, 'Article list'!$A$2:$A$995, 'Article list'!$H$2:$H$995, ""), AND(_xlpm.lookup_val <> "", _xlpm.lookup_val <> 0) ) )), _xlpm.total_count, COUNTA(_xlpm.ids), _xlpm.excluded_count, SUM(--_xlpm.status_list), _xlfn.IFS( _xlpm.excluded_count = _xlpm.total_count, TRUE, _xlpm.excluded_count = 0, FALSE, TRUE, "partial" ) )} -> TRUE | C3: Safety | D3: Personal Safety | F3: ? | M3: Building front/facxade | N3: ['Delphi', "Kendall's coefficient", "Cronbach's alpha value"]
A4: 1 | B4: {=_xlfn.LET( _xlpm.ids, VALUE(_xlfn.TEXTSPLIT(SUBSTITUTE(A4,",",";"), ";", " ", TRUE)), _xlpm.status_list, _xlfn.MAP(_xlpm.ids, _xlfn.LAMBDA(_xlpm.id, _xlfn.LET( _xlpm.lookup_val, _xlfn.XLOOKUP(_xlpm.id, 'Article list'!$A$2:$A$995, 'Article list'!$H$2:$H$995, ""), AND(_xlpm.lookup_val <> "", _xlpm.lookup_val <> 0) ) )), _xlpm.total_count, COUNTA(_xlpm.ids), _xlpm.excluded_count, SUM(--_xlpm.status_list), _xlfn.IFS( _xlpm.excluded_count = _xlpm.total_count, TRUE, _xlpm.excluded_count = 0, FALSE, TRUE, "partial" ) )} -> TRUE | C4: Safety | D4: Road Safety | E4: Pedestrian Infrastructure | F4: ? | G4: Presence | M4: Guard rails | N4: ['Delphi', "Kendall's coefficient", "Cronbach's alpha value"]
A5: 23 | B5: {=_xlfn.LET( _xlpm.ids, VALUE(_xlfn.TEXTSPLIT(SUBSTITUTE(A5,",",";"), ";", " ", TRUE)), _xlpm.status_list, _xlfn.MAP(_xlpm.ids, _xlfn.LAMBDA(_xlpm.id, _xlfn.LET( _xlpm.lookup_val, _xlfn.XLOOKUP(_xlpm.id, 'Article list'!$A$2:$A$995, 'Article list'!$H$2:$H$995, ""), AND(_xlpm.lookup_val <> "", _xlpm.lookup_val <> 0) ) )), _xlpm.total_count, COUNTA(_xlpm.ids), _xlpm.excluded_count, SUM(--_xlpm.status_list), _xlfn.IFS( _xlpm.excluded_count = _xlpm.total_count, TRUE, _xlpm.excluded_count = 0, FALSE, TRUE, "partial" ) )} -> FALSE | C5: Safety | D5: Road Safety | E5: Pedestrian Infrastructure | F5: ? | G5: Quality | M5: SN6 Streetscape design | N5: ['Design Analysis']
A6: 18 | B6: {=_xlfn.LET( _xlpm.ids, VALUE(_xlfn.TEXTSPLIT(SUBSTITUTE(A6,",",";"), ";", " ", TRUE)), _xlpm.status_list, _xlfn.MAP(_xlpm.ids, _xlfn.LAMBDA(_xlpm.id, _xlfn.LET( _xlpm.lookup_val, _xlfn.XLOOKUP(_xlpm.id, 'Article list'!$A$2:$A$995, 'Article list'!$H$2:$H$995, ""), AND(_xlpm.lookup_val <> "", _xlpm.lookup_val <> 0) ) )), _xlpm.total_count, COUNTA(_xlpm.ids), _xlpm.excluded_count, SUM(--_xlpm.status_list), _xlfn.IFS( _xlpm.excluded_count = _xlpm.total_count, TRUE, _xlpm.excluded_count = 0, FALSE, TRUE, "partial" ) )} -> FALSE | C6: Safety | D6: Personal Safety | E6: Public Services | F6: Fire station | G6: Proximity | H6: Distance (m) | M6: Distance to fire station | N6: ['Analytic Hierarchy Process (AHP)']
A7: 16 | B7: {=_xlfn.LET( _xlpm.ids, VALUE(_xlfn.TEXTSPLIT(SUBSTITUTE(A7,",",";"), ";", " ", TRUE)), _xlpm.status_list, _xlfn.MAP(_xlpm.ids, _xlfn.LAMBDA(_xlpm.id, _xlfn.LET( _xlpm.lookup_val, _xlfn.XLOOKUP(_xlpm.id, 'Article list'!$A$2:$A$995, 'Article list'!$H$2:$H$995, ""), AND(_xlpm.lookup_val <> "", _xlpm.lookup_val <> 0) ) )), _xlpm.total_count, COUNTA(_xlpm.ids), _xlpm.excluded_count, SUM(--_xlpm.status_list), _xlfn.IFS( _xlpm.excluded_count = _xlpm.total_count, TRUE, _xlpm.excluded_count = 0, FALSE, TRUE, "partial" ) )} -> FALSE | C7: Safety | D7: Personal Safety | E7: Public Services | F7: Fire station | G7: Quantity | M7: Number of fire station | N7: ['Exploratory Factor Analysis', 'Standard Deviational Ellipse,', 'Hot Spot Analysis,', 'Network Analysis']
A8: 23 | B8: {=_xlfn.LET( _xlpm.ids, VALUE(_xlfn.TEXTSPLIT(SUBSTITUTE(A8,",",";"), ";", " ", TRUE)), _xlpm.status_list, _xlfn.MAP(_xlpm.ids, _xlfn.LAMBDA(_xlpm.id, _xlfn.LET( _xlpm.lookup_val, _xlfn.XLOOKUP(_xlpm.id, 'Article list'!$A$2:$A$995, 'Article list'!$H$2:$H$995, ""), AND(_xlpm.lookup_val <> "", _xlpm.lookup_val <> 0) ) )), _xlpm.total_count, COUNTA(_xlpm.ids), _xlpm.excluded_count, SUM(--_xlpm.status_list), _xlfn.IFS( _xlpm.excluded_count = _xlpm.total_count, TRUE, _xlpm.excluded_count = 0, FALSE, TRUE, "partial" ) )} -> FALSE | C8: Safety | D8: Road Safety | E8: Pedestrian Infrastructure | F8: Footpaths | G8: Quality | M8: SN10 Walking friendly environment | N8: ['Design Analysis']
A9: 23 | B9: {=_xlfn.LET( _xlpm.ids, VALUE(_xlfn.TEXTSPLIT(SUBSTITUTE(A9,",",";"), ";", " ", TRUE)), _xlpm.status_list, _xlfn.MAP(_xlpm.ids, _xlfn.LAMBDA(_xlpm.id, _xlfn.LET( _xlpm.lookup_val, _xlfn.XLOOKUP(_xlpm.id, 'Article list'!$A$2:$A$995, 'Article list'!$H$2:$H$995, ""), AND(_xlpm.lookup_val <> "", _xlpm.lookup_val <> 0) ) )), _xlpm.total_count, COUNTA(_xlpm.ids), _xlpm.excluded_count, SUM(--_xlpm.status_list), _xlfn.IFS( _xlpm.excluded_count = _xlpm.total_count, TRUE, _xlpm.excluded_count = 0, FALSE, TRUE, "partial" ) )} -> FALSE | C9: Safety | D9: Road Safety | E9: Pedestrian Infrastructure | F9: Footpaths | G9: Quantity | M9: SN2 Total footpath provision | N9: ['Design Analysis']
A10: 23 | B10: {=_xlfn.LET( _xlpm.ids, VALUE(_xlfn.TEXTSPLIT(SUBSTITUTE(A10,",",";"), ";", " ", TRUE)), _xlpm.status_list, _xlfn.MAP(_xlpm.ids, _xlfn.LAMBDA(_xlpm.id, _xlfn.LET( _xlpm.lookup_val, _xlfn.XLOOKUP(_xlpm.id, 'Article list'!$A$2:$A$995, 'Article list'!$H$2:$H$995, ""), AND(_xlpm.lookup_val <> "", _xlpm.lookup_val <> 0) ) )), _xlpm.total_count, COUNTA(_xlpm.ids), _xlpm.excluded_count, SUM(--_xlpm.status_list), _xlfn.IFS( _xlpm.excluded_count = _xlpm.total_count, TRUE, _xlpm.excluded_count = 0, FALSE, TRUE, "partial" ) )} -> FALSE | C10: Safety | D10: Road Safety | E10: Pedestrian Infrastructure | F10: Footpaths | G10: Quality | M10: SN5 Appropriate width of the footpaths and side walks | N10: ['Design Analysis']
A11: 12 | B11: {=_xlfn.LET( _xlpm.ids, VALUE(_xlfn.TEXTSPLIT(SUBSTITUTE(A11,",",";"), ";", " ", TRUE)), _xlpm.status_list, _xlfn.MAP(_xlpm.ids, _xlfn.LAMBDA(_xlpm.id, _xlfn.LET( _xlpm.lookup_val, _xlfn.XLOOKUP(_xlpm.id, 'Article list'!$A$2:$A$995, 'Article list'!$H$2:$H$995, ""), AND(_xlpm.lookup_val <> "", _xlpm.lookup_val <> 0) ) )), _xlpm.total_count, COUNTA(_xlpm.ids), _xlpm.excluded_count, SUM(--_xlpm.status_list), _xlfn.IFS( _xlpm.excluded_count = _xlpm.total_count, TRUE, _xlpm.excluded_count = 0, FALSE, TRUE, "partial" ) )} -> FALSE | C11: Safety | D11: Personal Safety | E11: Public services | F11: Opinion | G11: Quality | H11: Area? | I11: Participación ciudadana | M11: Contact with city officials | N11: ['Likert Scale Measurement', 'One-Way ANOVA', 'Descriptive Statistics', 'Post Hoc (Tukey) Test', 'Mann-Whitney U Test', 'Qualitative Thematic Analysis']
A12: 12 | B12: {=_xlfn.LET( _xlpm.ids, VALUE(_xlfn.TEXTSPLIT(SUBSTITUTE(A12,",",";"), ";", " ", TRUE)), _xlpm.status_list, _xlfn.MAP(_xlpm.ids, _xlfn.LAMBDA(_xlpm.id, _xlfn.LET( _xlpm.lookup_val, _xlfn.XLOOKUP(_xlpm.id, 'Article list'!$A$2:$A$995, 'Article list'!$H$2:$H$995, ""), AND(_xlpm.lookup_val <> "", _xlpm.lookup_val <> 0) ) )), _xlpm.total_count, COUNTA(_xlpm.ids), _xlpm.excluded_count, SUM(--_xlpm.status_list), _xlfn.IFS( _xlpm.excluded_count = _xlpm.total_count, TRUE, _xlpm.excluded_count = 0, FALSE, TRUE, "partial" ) )} -> FALSE | C12: Safety | D12: Personal Safety | E12: Public services | F12: Opinion | G12: Perception | M12: Overall perception of safety | N12: ['Likert Scale Measurement', 'One-Way ANOVA', 'Descriptive Statistics', 'Post Hoc (Tukey) Test', 'Mann-Whitney U Test', 'Qualitative Thematic Analysis']
A13: 12 | B13: {=_xlfn.LET( _xlpm.ids, VALUE(_xlfn.TEXTSPLIT(SUBSTITUTE(A13,",",";"), ";", " ", TRUE)), _xlpm.status_list, _xlfn.MAP(_xlpm.ids, _xlfn.LAMBDA(_xlpm.id, _xlfn.LET( _xlpm.lookup_val, _xlfn.XLOOKUP(_xlpm.id, 'Article list'!$A$2:$A$995, 'Article list'!$H$2:$H$995, ""), AND(_xlpm.lookup_val <> "", _xlpm.lookup_val <> 0) ) )), _xlpm.total_count, COUNTA(_xlpm.ids), _xlpm.excluded_count, SUM(--_xlpm.status_list), _xlfn.IFS( _xlpm.excluded_count = _xlpm.total_count, TRUE, _xlpm.excluded_count = 0, FALSE, TRUE, "partial" ) )} -> FALSE | C13: Safety | D13: Personal Safety | E13: Public services | F13: Opinion | G13: Perception | M13: Perceived degree of crime | N13: ['Likert Scale Measurement', 'One-Way ANOVA', 'Descriptive Statistics', 'Post Hoc (Tukey) Test', 'Mann-Whitney U Test', 'Qualitative Thematic Analysis']
A14: 12 | B14: {=_xlfn.LET( _xlpm.ids, VALUE(_xlfn.TEXTSPLIT(SUBSTITUTE(A14,",",";"), ";", " ", TRUE)), _xlpm.status_list, _xlfn.MAP(_xlpm.ids, _xlfn.LAMBDA(_xlpm.id, _xlfn.LET( _xlpm.lookup_val, _xlfn.XLOOKUP(_xlpm.id, 'Article list'!$A$2:$A$995, 'Article list'!$H$2:$H$995, ""), AND(_xlpm.lookup_val <> "", _xlpm.lookup_val <> 0) ) )), _xlpm.total_count, COUNTA(_xlpm.ids), _xlpm.excluded_count, SUM(--_xlpm.status_list), _xlfn.IFS( _xlpm.excluded_count = _xlpm.total_count, TRUE, _xlpm.excluded_count = 0, FALSE, TRUE, "partial" ) )} -> FALSE | C14: Safety | D14: Personal Safety | E14: Public services | F14: Opinion | G14: Perception | M14: Perceived fairness of taxation | N14: ['Likert Scale Measurement', 'One-Way ANOVA', 'Descriptive Statistics', 'Post Hoc (Tukey) Test', 'Mann-Whitney U Test', 'Qualitative Thematic Analysis']
A15: 11 | B15: {=_xlfn.LET( _xlpm.ids, VALUE(_xlfn.TEXTSPLIT(SUBSTITUTE(A15,",",";"), ";", " ", TRUE)), _xlpm.status_list, _xlfn.MAP(_xlpm.ids, _xlfn.LAMBDA(_xlpm.id, _xlfn.LET( _xlpm.lookup_val, _xlfn.XLOOKUP(_xlpm.id, 'Article list'!$A$2:$A$995, 'Article list'!$H$2:$H$995, ""), AND(_xlpm.lookup_val <> "", _xlpm.lookup_val <> 0) ) )), _xlpm.total_count, COUNTA(_xlpm.ids), _xlpm.excluded_count, SUM(--_xlpm.status_list), _xlfn.IFS( _xlpm.excluded_count = _xlpm.total_count, TRUE, _xlpm.excluded_count = 0, FALSE, TRUE, "partial" ) )} -> TRUE | C15: Safety | D15: Personal Safety | E15: Public services | F15: Opinion | G15: Perception | M15: Perceived safety during day-time and night-time | N15: ['Distance-based accessibility measures', 'Objective environmental and neighbourhood indicators', 'Resident perception surveys using 5-point Likert scales', 'Satisfaction-based scoring for each livability dimension']
A16: 12 | B16: {=_xlfn.LET( _xlpm.ids, VALUE(_xlfn.TEXTSPLIT(SUBSTITUTE(A16,",",";"), ";", " ", TRUE)), _xlpm.status_list, _xlfn.MAP(_xlpm.ids, _xlfn.LAMBDA(_xlpm.id, _xlfn.LET( _xlpm.lookup_val, _xlfn.XLOOKUP(_xlpm.id, 'Article list'!$A$2:$A$995, 'Article list'!$H$2:$H$995, ""), AND(_xlpm.lookup_val <> "", _xlpm.lookup_val <> 0) ) )), _xlpm.total_count, COUNTA(_xlpm.ids), _xlpm.excluded_count, SUM(--_xlpm.status_list), _xlfn.IFS( _xlpm.excluded_count = _xlpm.total_count, TRUE, _xlpm.excluded_count = 0, FALSE, TRUE, "partial" ) )} -> FALSE | C16: Safety | D16: Personal Safety | E16: Public services | F16: Opinion | G16: Quantity | M16: Petty crimes (shoplifting, bag snatching, pickpocketing) | N16: ['Likert Scale Measurement', 'One-Way ANOVA', 'Descriptive Statistics', 'Post Hoc (Tukey) Test', 'Mann-Whitney U Test', 'Qualitative Thematic Analysis']
A17: 26 | B17: {=_xlfn.LET( _xlpm.ids, VALUE(_xlfn.TEXTSPLIT(SUBSTITUTE(A17,",",";"), ";", " ", TRUE)), _xlpm.status_list, _xlfn.MAP(_xlpm.ids, _xlfn.LAMBDA(_xlpm.id, _xlfn.LET( _xlpm.lookup_val, _xlfn.XLOOKUP(_xlpm.id, 'Article list'!$A$2:$A$995, 'Article list'!$H$2:$H$995, ""), AND(_xlpm.lookup_val <> "", _xlpm.lookup_val <> 0) ) )), _xlpm.total_count, COUNTA(_xlpm.ids), _xlpm.excluded_count, SUM(--_xlpm.status_list), _xlfn.IFS( _xlpm.excluded_count = _xlpm.total_count, TRUE, _xlpm.excluded_count = 0, FALSE, TRUE, "partial" ) )} -> FALSE | C17: Safety | D17: Personal Safety | F17: Opinion | G17: Perception | M17: Improvement in public perception of safety from a rating of 3 to 2 on a 5-point scale; Security | N17: ['Delphi method', 'GIS-based spatial analysis'] | O17: Perception
